Workbook
Name dr: DCF!$E$18
Name tg: DCF!$E$19
Name tGR: DCF!$E$19
Name WACC: DCF!$E$18

Sheet DCF
B2: DCF
B4: Ticker | C4: PLTR | E4: Current Stock Price | H4: 69.85
B5: Date | C5: 45630 | E5: Implied Share Price | H5: =P83 -> 10.053176
B6: Year End | C6: 45657 | E6: Upside / (Downside) | H6: =H5/H4-1 -> -0.85607479
B8: Assumptions
B10: Switches | G10: Conservative | L10: Base | Q10: Optimistic
B11: Assumptions | G11: Assumptions | I11: Year | J11: Metric | L11: Assumptions | N11: Year | O11: Metric | Q11: Assumptions | S11: Year | T11: Metric
B12: Revenue | E12: 3 | G12: Revenue | I12: 2025 | J12: 0.95 | Q12: Revenue | S12: 2025 | T12: 1.1
B13: EBIT | E13: 3 | G13: Revenue | I13: '26 - '29 | J13: 0.7 | L13: =G13 -> Revenue | N13: =I13 -> '26 - '29 | O13: 0.85 | Q13: Revenue | S13: =N13 -> '26 - '29 | T13: 0.9
B14: WACC | E14: 3 | G14: EBIT | I14: 2029 | J14: 0.41 | L14: =G14 -> EBIT | N14: 2029 | O14: 0.425 | Q14: =L14 -> EBIT | T14: 0.44
B15: TGR | E15: 3
B17: Valuation
B18: WACC | E18: =CHOOSE(E14,J18,O18,T18) -> 0.09 | G18: WACC | J18: 0.144 | L18: WACC | O18: 0.11 | Q18: WACC | T18: 0.09
B19: TGR | E19: =J19 -> 2.5% | G19: TGR | J19: 2.5% | L19: TGR | O19: 2.5% | Q19: TGR | T19: 0.03
B21: Income Statement (12/31, USD M) | E21: 2018 | F21: =E21+1 -> 2019 | G21: =F21+1 -> 2020 | H21: =G21+1 -> 2021 | I21: =H21+1 -> 2022 | J21: =I21+1 -> 2023 | K21: =J21+1 -> 2024 | L21: =K21+1 -> 2025 | M21: =L21+1 -> 2026
B22: Revenue | E22: ='IS - Annual'!B10 -> 595.409 | F22: ='IS - Annual'!C10 -> 742.555 | G22: ='IS - Annual'!D10 -> 1092.673 | H22: ='IS - Annual'!E10 -> 1541.889 | I22: ='IS - Annual'!F10 -> 1905.871 | J22: ='IS - Annual'!G10 -> 2225.012 | K22: ='IS - Estimates'!B5 -> 2809.51 | L22: ='IS - Estimates'!C5 -> 3512.98 | M22: ='IS - Estimates'!D5 -> 4216.33
B23: % growth | E23: -- | F23: =F22/E22-1 -> 0.24713432 | G23: =G22/F22-1 -> 0.47150447 | H23: =H22/G22-1 -> 0.41111659 | I23: =I22/H22-1 -> 0.23606239 | J23: =J22/I22-1 -> 0.16745152 | K23: =K22/J22-1 -> 0.26269431 | L23: =L22/K22-1 -> 0.25038886 | M23: =M22/L22-1 -> 0.20021463
B25: EBIT | E25: ='IS - Annual'!B20 -> -623.44 | F25: ='IS - Annual'!C20 -> -576.444 | G25: ='IS - Annual'!D20 -> -1173.679 | H25: ='IS - Annual'!E20 -> -411.046 | I25: ='IS - Annual'!F20 -> -161.201 | J25: ='IS - Annual'!G20 -> 119.966 | K25: ='IS - Estimates'!B9 -> 1062.1 | L25: ='IS - Estimates'!C9 -> 1354.47 | M25: ='IS - Estimates'!D9 -> 1653.59
B26: % of sales | E26: =E25/E22 -> -1.0470786 | F26: =F25/F22 -> -0.77629805 | G26: =G25/G22 -> -1.0741356 | H26: =H25/H22 -> -0.26658599 | I26: =I25/I22 -> -0.084581275 | J26: =J25/J22 -> 0.053917013 | K26: =K25/K22 -> 0.37803745 | L26: =L25/L22 -> 0.38556155 | M26: =M25/M22 -> 0.39218704
B28: Taxes | E28: ='IS - Annual'!B32 -> 9.102 | F28: ='IS - Annual'!C32 -> 12.375 | G28: ='IS - Annual'!D32 -> -12.636 | H28: ='IS - Annual'!E32 -> 31.885 | I28: ='IS - Annual'!F32 -> 10.067 | J28: ='IS - Annual'!G32 -> 19.716
B29: Tax rate | E29: =E28/'IS - Annual'!B31 -> -0.015942549 | F29: =F28/'IS - Annual'!C31 -> -0.02181497 | G29: =G28/'IS - Annual'!D31 -> 0.010717312 | H29: =H28/'IS - Annual'!E31 -> -0.06527204 | I29: =I28/'IS - Annual'!F31 -> -0.027884341 | J29: =J28/'IS - Annual'!G31 -> 0.083157944
B31: Cash Flow Items (12/31, USD M) | E31: 2018 | F31: =E31+1 -> 2019 | G31: =F31+1 -> 2020 | H31: =G31+1 -> 2021 | I31: =H31+1 -> 2022 | J31: =I31+1 -> 2023
B32: D&A | E32: ='CFS - Annual'!B12 -> 13.91 | F32: ='CFS - Annual'!C12 -> 12.255 | G32: ='CFS - Annual'!D12 -> 13.871 | H32: ='CFS - Annual'!E12 -> 14.897 | I32: ='CFS - Annual'!F12 -> 22.522 | J32: ='CFS - Annual'!G12 -> 33.354
B33: % of sales | E33: =E32/E22 -> 0.023362092 | F33: =F32/F22 -> 0.016503828 | G33: =G32/G22 -> 0.012694557 | H33: =H32/H22 -> 0.0096615256 | I33: =I32/I22 -> 0.011817169 | J33: =J32/J22 -> 0.014990481
B35: CapEx | E35: ='CFS - Annual'!B25 -> -15.404 | F35: ='CFS - Annual'!C25 -> -13.096 | G35: ='CFS - Annual'!D25 -> -12.236 | H35: ='CFS - Annual'!E25 -> -12.627 | I35: ='CFS - Annual'!F25 -> -40.027 | J35: ='CFS - Annual'!G25 -> -15.114
B36: % of sales | E36: =E35/E22 -> -0.025871292 | F36: =F35/F22 -> -0.017636404 | G36: =G35/G22 -> -0.011198227 | H36: =H35/H22 -> -0.0081893055 | I36: =I35/I22 -> -0.021001946 | J36: =J35/J22 -> -0.0067927724
B38: Change in NWC | E38: ='CFS - Annual'!B18 -> 302.575 | F38: ='CFS - Annual'!C18 -> 134.027 | G38: ='CFS - Annual'!D18 -> -454.119 | H38: ='CFS - Annual'!E18 -> -92.052 | I38: ='CFS - Annual'!F18 -> -267.103 | J38: ='CFS - Annual'!G18 -> 6.236
B39: % of sales | E39: =E38/E22 -> 0.50818009 | F39: =F38/F22 -> 0.18049437 | G39: =G38/G22 -> -0.41560375 | H39: =H38/H22 -> -0.059700796 | I39: =I38/I22 -> -0.14014747 | J39: =J38/J22 -> 0.0028026815
B40: % of change in sales | E40: =E23 -> -- | F40: =F38/(F22-E22) -> 0.91084365 | G40: =G38/(G22-F22) -> -1.2970456 | H40: =H38/(H22-G22) -> -0.20491701 | I40: =I38/(I22-H22) -> -0.73383574 | J40: =J38/(J22-I22) -> 0.019539953
B42: DCF (12/31, USD M) | E42: 2018 | F42: =E42+1 -> 2019 | G42: =F42+1 -> 2020 | H42: =G42+1 -> 2021 | I42: =H42+1 -> 2022 | J42: =I42+1 -> 2023 | K42: =J42+1 -> 2024 | L42: =K42+1 -> 2025 | M42: =L42+1 -> 2026 | ... P42: =O42+1 -> 2029
B43: Revenue | E43: =DCF!E22 -> 595.409 | F43: =DCF!F22 -> 742.555 | G43: =DCF!G22 -> 1092.673 | H43: =DCF!H22 -> 1541.889 | I43: =DCF!I22 -> 1905.871 | J43: =DCF!J22 -> 2225.012 | K43: =J43*(1+K44) -> 2854.0102 | L43: =K43*(1+L44) -> 3640.0838 | M43: =L43*(1+M44) -> 4542.4059 | N43: =M43*(1+N44) -> 5555.8006 | O43: =N43*(1+O44) -> 6671.3322 | P43: =O43*(1+P44) -> 7876.8963
B44: % growth | E44: =E23 -> -- | F44: =F23 -> 0.24713432 | G44: =G23 -> 0.47150447 | H44: =H23 -> 0.41111659 | I44: =I23 -> 0.23606239 | J44: =J23 -> 0.16745152 | K44: =OFFSET(K44,$E$12,0) -> 0.28269431 | L44: =OFFSET(L44,$E$12,0) -> 0.27542774 | M44: =OFFSET(M44,$E$12,0) -> 0.24788497 | N44: =OFFSET(N44,$E$12,0) -> 0.22309647 | O44: =OFFSET(O44,$E$12,0) -> 0.20078683 | P44: =OFFSET(P44,$E$12,0) -> 0.18070814
B45: Conservative | K45: =K23-1% -> 0.25269431 | L45: =L46*J12 -> 0.23786941 | M45: =L45*$J$13 -> 0.16650859 | N45: =M45*$J$13 -> 0.11655601 | O45: =N45*$J$13 -> 0.081589209 | P45: =O45*$J$13 -> 0.057112447
B46: Base (Street) | K46: =$K$23 -> 0.26269431 | L46: =L23 -> 0.25038886 | M46: =L46*$O$13 -> 0.21283053 | N46: =M46*$O$13 -> 0.18090595 | O46: =N46*$O$13 -> 0.15377006 | P46: =O46*$O$13 -> 0.13070455
B47: Optimistic | K47: =$K$23+2% -> 0.28269431 | L47: =L46*T12 -> 0.27542774 | M47: =L47*$T$13 -> 0.24788497 | N47: =M47*$T$13 -> 0.22309647 | O47: =N47*$T$13 -> 0.20078683 | P47: =O47*$T$13 -> 0.18070814 | R47: aggressive optimism
B49: EBIT | E49: =E25 -> -623.44 | F49: =F25 -> -576.444 | G49: =G25 -> -1173.679 | H49: =H25 -> -411.046 | I49: =I25 -> -161.201 | J49: =J25 -> 119.966 | K49: =K50*K43 -> 1107.4629 | L49: =L50*L43 -> 1450.3185 | M49: =M50*M43 -> 1857.0376 | N49: =N50*N43 -> 2329.0749 | O49: =O50*O43 -> 2866.0543 | P49: =P50*P43 -> 3465.8344
B50: % of sales | E50: =E26 -> -1.0470786 | F50: =F26 -> -0.77629805 | G50: =G26 -> -1.0741356 | H50: =H26 -> -0.26658599 | I50: =I26 -> -0.084581275 | J50: =J26 -> 0.053917013 | K50: =OFFSET(K50,$E$13,0) -> 0.38803745 | L50: =OFFSET(L50,$E$13,0) -> 0.39842996 | M50: =OFFSET(M50,$E$13,0) -> 0.40882247 | N50: =OFFSET(N50,$E$13,0) -> 0.41921498 | O50: =OFFSET(O50,$E$13,0) -> 0.42960749 | P50: =OFFSET(P50,$E$13,0) -> 0.44
B51: Conservative | K51: =K52-1% -> 0.36803745 | L51: =K51+(($P51-K$51)/($P$42-$K$42)) -> 0.37642996 | M51: =L51+(($P51-L$51)/($P$42-$K$42)) -> 0.38314397 | N51: =M51+(($P51-M$51)/($P$42-$K$42)) -> 0.38851518 | O51: =N51+(($P51-N$51)/($P$42-$K$42)) -> 0.39281214 | P51: =J14 -> 0.41
B52: Base (Street) | K52: =K26 -> 0.37803745 | L52: =K52+(($P52-$K52)/($P$42-$K$42)) -> 0.38742996 | M52: =L52+(($P52-$K52)/($P$42-$K$42)) -> 0.39682247 | N52: =M52+(($P52-$K52)/($P$42-$K$42)) -> 0.40621498 | O52: =N52+(($P52-$K52)/($P$42-$K$42)) -> 0.41560749 | P52: =O14 -> 0.425
B53: Optimistic | K53: =K52+1% -> 0.38803745 | L53: =K53+(($P53-$K53)/($P$42-$K$42)) -> 0.39842996 | M53: =L53+(($P53-$K53)/($P$42-$K$42)) -> 0.40882247 | N53: =M53+(($P53-$K53)/($P$42-$K$42)) -> 0.41921498 | O53: =N53+(($P53-$K53)/($P$42-$K$42)) -> 0.42960749 | P53: =T14 -> 0.44
...

Sheet WACC
B2: WACC
N6: WACC = % of equity x cost of equity + % of debt x cost of debt x (1 - Tax Rate)
B7: WACC | N7: Cost of equity = Risk free rate + Beta x Market Risk Premium
B8: Market Cap | F8: 181.3
B9: % of Equity | F9: =F8/$F$20 -> 1
B10: Cost of Equity | F10: =F11+F12*F13 -> 0.14425
B11: Risk Free Rate | F11: 0.04184
B12: Beta | F12: 2.66
B13: Market Risk Premium | F13: 0.0385
B15: Debt | F15: 0
B16: % of Debt | F16: =F15/$F$20 -> 0
B17: Cost of Debt | F17: 0
B18: Tax Rate | F18: 0.14
B20: Total | F20: =F8+F15 -> 181.3
B22: WACC | F22: =F9*F10+(F16*F17*(1-F18)) -> 0.14425

Sheet Shares
B2: Diluted Share Count Calculation
B4: Full Diluted Shares
B6: Current price | E6: 69.85
B7: Basic shares outstanding (latest filing) | E7: =SUM(2180.654456,96.361544,1.005) -> 2278.021
B8: In-the-money exercisable options | E8: =E32 -> 281.32
B9: Total proceeds ($mm) | E9: =SUMPRODUCT(D21:D30,E21:E30) -> 4558.1506
B10: Total shares repurchased (mm) | E10: =E9/E6 -> 65.256272
B11: Net dilutive options | E11: =E8-E10 -> 216.06373
B13: RSUs | E13: 72.201
B14: PSUs | E14: 0.862
B16: Net diluted shares outstanding | E16: =E7+E11+E13+E14 -> 2567.1477
B18: Options outstanding
C20: Outstanding | D20: Exercise price | E20: Dilutive Shares
B21: 1 | C21: 233.357 | D21: 9.1 | E21: =IF(D21<$E$6,C21) -> 233.357
B22: =B21+1 -> 2 | C22: 47.963 | D22: 50.76 | E22: =IF(D22<$E$6,C22) -> 47.963
B23: =B22+1 -> 3 | E23: =IF(D23<$E$6,C23) -> 0
B24: =B23+1 -> 4 | E24: =IF(D24<$E$6,C24) -> 0
B25: =B24+1 -> 5 | E25: =IF(D25<$E$6,C25) -> 0
B26: =B25+1 -> 6 | E26: =IF(D26<$E$6,C26) -> 0
B27: =B26+1 -> 7 | E27: =IF(D27<$E$6,C27) -> 0
B28: =B27+1 -> 8 | E28: =IF(D28<$E$6,C28) -> 0
B29: =B28+1 -> 9 | E29: =IF(D29<$E$6,C29) -> 0
B30: =B29+1 -> 10 | E30: =IF(D30<$E$6,C30) -> 0
B32: Total | E32: =SUM(E21:E30) -> 281.32

Sheet IS - Estimates
A1: PLTR-US
A2: Income Statement (M)
B3: CY '24E | C3: CY '25E | D3: CY '26E
B4: Dec '24E | C4: Dec '25E | D4: Dec '26E
A5: Sales | B5: 2809.51 | C5: 3512.98 | D5: 4216.33
A6: Cost of Sales | B6: 512.633 | C6: 608.373 | D6: 722.247
A7: Gross Income | B7: 2119.49 | C7: 2671.27 | D7: 3485.86
A8: EBITDA | B8: 1075.12 | C8: 1349.51 | D8: 1624.87
A9: Operating Income | B9: 1062.1 | C9: 1354.47 | D9: 1653.59
A10: Pretax Income | B10: 1161.49 | C10: 1418.81 | D10: 1780.83
A11: Tax Expense | B11: 217.612 | C11: 314.059 | D11: 328.05
A12: Net Income | B12: 931.729 | C12: 1201.65 | D12: 1477.42

Sheet IS - Annual
A1: Palantir Technologies Inc. Class A (PLTR)
A2: $68.92
A5: Palantir Technologies Inc. Class A
A6: PLTR 69608A108 BN78DQ4 NASDAQ Common stock
A7: Source: FactSet Fundamentals
B8: DEC '18 | C8: DEC '19 | D8: DEC '20 | E8: DEC '21 | F8: DEC '22 | G8: DEC '23 | H8: SEP '24
H9: LTM
A10: Sales | B10: 595.409 | C10: 742.555 | D10: 1092.673 | E10: 1541.889 | F10: 1905.871 | G10: 2225.012 | H10: 2646.338
A11: Cost of Goods Sold (COGS) incl. D&A | B11: 165.401 | C11: 242.373 | D11: 352.547 | E11: 339.404 | F11: 408.549 | G11: 431.105 | H11: 500.096
A12: COGS excluding D&A | B12: 151.601 | C12: 230.173 | D12: 338.676 | E12: 324.507 | F12: 386.027 | G12: 397.751 | H12: 467.543
A13: Depreciation & Amortization Expense | B13: 13.8 | C13: 12.2 | D13: 13.871 | E13: 14.897 | F13: 22.522 | G13: 33.354 | H13: 32.553
A14: Depreciation | B14: 13.8 | C14: 12.2 | D14: 13.871 | E14: 14.897 | F14: 22.522 | G14: 33.354 | H14: 30.566
A15: Amortization of Intangibles | F15: 0 | G15: 0 | H15: 1.987
A16: Gross Income | B16: 430.008 | C16: 500.182 | D16: 740.126 | E16: 1202.485 | F16: 1497.322 | G16: 1793.907 | H16: 2146.242
A17: SG&A Expense | B17: 1053.448 | C17: 1076.626 | D17: 1913.805 | E17: 1613.531 | F17: 1658.523 | G17: 1673.941 | H17: 1781.088
A18: Research & Development | B18: 285.451 | C18: 305.563 | D18: 560.66 | E18: 387.487 | F18: 359.679 | G18: 404.624 | H18: 445.659
A19: Other SG&A | B19: 767.997 | C19: 771.063 | D19: 1353.145 | E19: 1226.044 | F19: 1298.844 | G19: 1269.317 | H19: 1335.429
A20: EBIT (Operating Income) | B20: -623.44 | C20: -576.444 | D20: -1173.679 | E20: -411.046 | F20: -161.201 | G20: 119.966 | H20: 365.154
A21: Nonoperating Income - Net | B21: 7.862 | C21: 12.237 | D21: 7.98 | E21: -73.808 | F21: -81.068 | G21: -159.705 | H21: 459.964
A22: Nonoperating Interest Income | B22: 10.5 | C22: 15.09 | D22: 4.68 | E22: 1.607 | F22: 20.309 | G22: 132.572 | H22: 186.61
A23: Other Income (Expense) | B23: -2.638 | C23: -2.853 | D23: 3.3 | E23: -75.415 | F23: -101.377 | G23: -292.277 | H23: 273.354
A24: Interest Expense | B24: 3.44 | C24: 3.061 | D24: 14.139 | E24: 3.64 | F24: 4.058 | G24: 3.47 | H24: 0.136
A25: Gross Interest Expense | B25: 3.44 | C25: 3.061 | D25: 14.139 | E25: 3.64 | F25: 4.058 | G25: 3.47 | H25: 0.136
A26: Unusual Expense - Net | B26: -48.093 | C26: 0.003 | D26: -0.811 | E26: 0 | F26: 114.7 | G26: -280.3 | H26: 310.1
A27: Restructuring Expense | B27: 0 | C27: 0 | D27: 0 | E27: 0 | F27: -44.3 | G27: -44.3 | H27: -44.3
A28: Unrealized Valuation Gain/Loss | B28: 48.093 | C28: -0.003 | D28: 0.811 | F28: -159 | G28: 236 | H28: -354.4
A29: Investments | F29: -159 | G29: 236 | H29: -354.4
A30: Hedges/Derivatives | B30: 48.093 | C30: -0.003 | D30: 0.811
A31: Pretax Income | B31: -570.925 | C31: -567.271 | D31: -1179.027 | E31: -488.494 | F31: -361.027 | G31: 237.091 | H31: 514.882
A32: Income Taxes | B32: 9.102 | C32: 12.375 | D32: -12.636 | E32: 31.885 | F32: 10.067 | G32: 19.716 | H32: 26.987
A33: Income Taxes - Current Domestic | B33: 0.142 | C33: 0.139 | D33: 0.5 | E33: -0.088 | F33: 0.765 | G33: 2.333
A34: Income Taxes - Current Foreign | B34: 15.945 | C34: 19.435 | D34: 7.249 | E34: -11.343 | F34: 9.476 | G34: 22.189
A35: Income Taxes - Deferred Domestic | B35: 0 | C35: 0 | D35: 0 | E35: -0.111 | F35: 0 | G35: 0
A36: Income Taxes - Deferred Foreign | B36: -6.985 | C36: -7.199 | D36: -20.385 | E36: 43.427 | F36: -0.174 | G36: -4.806
A37: Other After Tax Adjustments | B37: 0 | C37: -8.481 | D37: -5.483 | E37: 0 | F37: 0 | G37: 0 | H37: 0
A38: Consolidated Net Income | B38: -580.027 | C38: -588.127 | D38: -1171.874 | E38: -520.379 | F38: -371.094 | G38: 217.375 | H38: 487.895
A39: Minority Interest | B39: 0 | C39: 0 | D39: 0 | E39: 0 | F39: 2.611 | G39: 7.55 | H39: 11.323
A40: Net Income | B40: -580.027 | C40: -588.127 | D40: -1171.874 | E40: -520.379 | F40: -373.705 | G40: 209.825 | H40: 476.572
A41: Preferred Dividends | B41: 18.098 | C41: 0 | D41: 0 | E41: 0 | F41: 0 | G41: 0 | H41: 0
A42: Net Income available to Common | B42: -598.125 | C42: -588.127 | D42: -1171.874 | E42: -520.379 | F42: -373.705 | G42: 209.825 | H42: 476.572
...

Sheet IS - Quarterly
A1: Palantir Technologies Inc. Class A (PLTR)
A2: $68.95
A5: Palantir Technologies Inc. Class A
A6: PLTR 69608A108 BN78DQ4 NASDAQ Common stock
A7: Source: FactSet Fundamentals
B8: JUN '22 | C8: SEP '22 | D8: DEC '22 | E8: MAR '23 | F8: JUN '23 | G8: SEP '23 | H8: DEC '23 | I8: MAR '24 | J8: JUN '24 | K8: SEP '24
A9: Sales | B9: 473.01 | C9: 477.88 | D9: 508.624 | E9: 525.186 | F9: 533.317 | G9: 558.159 | H9: 608.35 | I9: 634.338 | J9: 678.134 | K9: 725.516
A10: Cost of Goods Sold (COGS) incl. D&A | B10: 102.224 | C10: 107.611 | D10: 104.311 | E10: 107.645 | F10: 106.899 | G10: 107.922 | H10: 108.639 | I10: 116.256 | J10: 128.562 | K10: 146.639
A11: COGS excluding D&A | B11: 97.329 | C11: 102.918 | D11: 95.689 | E11: 99.325 | F11: 98.5 | G11: 99.259 | H11: 100.667 | I11: 107.818 | J11: 120.506 | K11: 138.552
A12: Depreciation & Amortization Expense | B12: 4.895 | C12: 4.693 | D12: 8.622 | E12: 8.32 | F12: 8.399 | G12: 8.663 | H12: 7.972 | I12: 8.438 | J12: 8.056 | K12: 8.087
A13: Depreciation | B13: 4.895 | C13: 4.693 | D13: 8.622 | E13: 8.32 | F13: 8.399 | G13: 8.663 | H13: 7.972 | I13: 8.438 | J13: 8.056 | K13: 6.1
A14: Amortization of Intangibles | B14: 0 | C14: 0 | D14: 0 | E14: 0 | F14: 0 | G14: 0 | H14: 0 | I14: 0 | J14: 0 | K14: 1.987
A15: Gross Income | B15: 370.786 | C15: 370.269 | D15: 404.313 | E15: 417.541 | F15: 426.418 | G15: 450.237 | H15: 499.711 | I15: 518.082 | J15: 549.572 | K15: 578.877
A16: SG&A Expense | B16: 412.531 | C16: 432.46 | D16: 422.139 | E16: 413.426 | F16: 416.344 | G16: 410.254 | H16: 433.917 | I16: 437.201 | J16: 444.233 | K16: 465.737
A17: Research & Development | B17: 88.171 | C17: 100.863 | D17: 82.044 | E17: 90.1 | F17: 99.533 | G17: 105.708 | H17: 109.283 | I17: 110.04 | J17: 108.781 | K17: 117.555
A18: Other SG&A | B18: 324.36 | C18: 331.597 | D18: 340.095 | E18: 323.326 | F18: 316.811 | G18: 304.546 | H18: 324.634 | I18: 327.161 | J18: 335.452 | K18: 348.182
A19: EBIT (Operating Income) | B19: -41.745 | C19: -62.191 | D19: -17.826 | E19: 4.115 | F19: 10.074 | G19: 39.983 | H19: 65.794 | I19: 80.881 | J19: 105.339 | K19: 113.14
A20: Nonoperating Income - Net | B20: -11.526 | C20: -41.506 | D20: -20.713 | E20: -351.808 | F20: -1078.714 | G20: -1359.272 | H20: 1160.289 | I20: 2329.845 | J20: -3064.58 | K20: 34.41
... A34: Net Income available to Common | B34: -179.329 | C34: -123.875 | D34: 30.878 | E34: 16.802 | F34: 28.127 | G34: 71.505 | H34: 93.391 | I34: 105.53 | J34: 134.126 | K34: 143.525
A35: Per Share
A36: EPS (recurring) | B36: -0.045439 | C36: -0.053671 | D36: -0.010796 | E36: -0.109161 | F36: -0.325646 | G36: -0.39065 | H36: 0.372043 | I36: 0.714772 | J36: -0.843118 | K36: 0.055621
A37: EPS (basic) | B37: -0.0873 | C37: -0.0598 | D37: 0.0148 | E37: 0.008 | F37: 0.0132 | G37: 0.0331 | H37: 0.0427 | I37: 0.0477 | J37: 0.0601 | K37: 0.0638
A38: Basic Shares Outstanding | B38: 2054.799 | C38: 2073.265 | D38: 2090.107 | E38: 2107.78 | F38: 2131.224 | G38: 2162.53 | H38: 2187.214 | I38: 2213.545 | J38: 2231.592 | K38: 2250.032
A39: Total Shares Outstanding | B39: 2062.741 | C39: 2079.664 | D39: 2099.075 | E39: 2117.73 | F39: 2149.98 | G39: 2175.241 | H39: 2200.128 | I39: 2226.963 | J39: 2237.939 | K39: 2269.809
A40: EPS (diluted) | B40: -0.0873 | C40: -0.0598 | D40: 0.014 | E40: 0.0076 | F40: 0.0124 | G40: 0.0308 | H40: 0.0396 | I40: 0.044 | J40: 0.0556 | K40: 0.0584
A41: Diluted Shares Outstanding | B41: 2054.799 | C41: 2073.265 | D41: 2203.733 | E41: 2217.439 | F41: 2278.155 | G41: 2325.6 | H41: 2357.742 | I41: 2400.107 | J41: 2414.696 | K41: 2459.589
A42: Total Shares Outstanding | B42: 2062.741 | C42: 2079.664 | D42: 2099.075 | E42: 2117.73 | F42: 2149.98 | G42: 2175.241 | H42: 2200.128 | I42: 2226.963 | J42: 2237.939 | K42: 2269.809
A43: Earnings Persistence | B43: 0 | C43: 0 | D43: 7.111 | E43: 0 | F43: 0 | G43: 0 | H43: 0 | I43: 2.085 | J43: 23.322 | K43: 26.542
A44: EBITDA
A45: EBITDA | B45: -36.85 | C45: -57.498 | D45: -9.204 | E45: 12.435 | F45: 18.473 | G45: 48.646 | H45: 73.766 | I45: 89.319 | J45: 113.395 | K45: 121.227
A46: EBIT | B46: -41.745 | C46: -62.191 | D46: -17.826 | E46: 4.115 | F46: 10.074 | G46: 39.983 | H46: 65.794 | I46: 80.881 | J46: 105.339 | K46: 113.14
A47: Depreciation & Amortization Expense | B47: 4.895 | C47: 4.693 | D47: 8.622 | E47: 8.32 | F47: 8.399 | G47: 8.663 | H47: 7.972 | I47: 8.438 | J47: 8.056 | K47: 8.087
A48: All figures in millions of U.S. Dollar except per share items.

Sheet CFS - Estimates
A1: PLTR-US
A2: Cash Flow (M)
B3: CY '24E | C3: CY '25E | D3: CY '26E
B4: Dec '24E | C4: Dec '25E | D4: Dec '26E
A5: Capital Expenditures | B5: 14.6864 | C5: 20.7433 | D5: 20
A6: Free Cash Flow | B6: 1067.54 | C6: 1283.59 | D6: -
A7: Unlevered Free Cash Flow | B7: - | C7: - | D7: -
A8: Cash Flow from Operations | B8: 1053.15 | C8: 1436.82 | D8: -
A9: Cash Flow from Investing | B9: -984.952 | C9: -21.7535 | D9: -
A10: Cash Flow from Financing | B10: 182.45 | C10: -400 | D10: -

Sheet CFS - Annual
A1: Palantir Technologies Inc. Class A (PLTR)
A2: $69.04
A5: Palantir Technologies Inc. Class A
A6: PLTR 69608A108 BN78DQ4 NASDAQ Common stock
A7: Source: FactSet Fundamentals
B8: DEC '18 | C8: DEC '19 | D8: DEC '20 | E8: DEC '21 | F8: DEC '22 | G8: DEC '23 | H8: SEP '24
H9: LTM
A10: Operating Activities
A11: Net Income / Starting Line | B11: -580.027 | C11: -579.646 | D11: -1166.391 | E11: -520.379 | F11: -371.094 | G11: 217.375 | H11: 487.895
A12: Depreciation, Depletion & Amortization | B12: 13.91 | C12: 12.255 | D12: 13.871 | E12: 14.897 | F12: 22.522 | G12: 33.354 | H12: 32.553
A13: Depreciation and Depletion | B13: 13.91 | C13: 12.255 | D13: 13.871 | E13: 14.897 | F13: 22.522 | G13: 33.354 | H13: 26.172
A14: Deferred Taxes & Investment Tax Credit | B14: 0 | C14: 0 | D14: 0 | E14: 43.316 | F14: -0.174 | G14: -4.806 | H14: -4.806
A15: Deferred Taxes | B15: 0 | C15: 0 | D15: 0 | E15: 43.316 | F15: -0.174 | G15: -4.806 | H15: -4.806
A16: Other Funds | B16: 224.53 | C16: 268.149 | D16: 1310.031 | E16: 888.069 | F16: 839.586 | G16: 460.024 | H16: 570.517
A17: Funds from Operations | B17: -341.587 | C17: -299.242 | D17: 157.511 | E17: 425.903 | F17: 490.84 | G17: 705.947 | H17: 1086.159
A18: Changes in Working Capital | B18: 302.575 | C18: 134.027 | D18: -454.119 | E18: -92.052 | F18: -267.103 | G18: 6.236 | H18: -91.449
A19: Receivables | B19: -10.483 | C19: -23.905 | D19: -108.476 | E19: -35.237 | F19: -77.519 | G19: -106.159 | H19: -258.106
A20: Accounts Payable | B20: 10.968 | C20: 23.424 | D20: -34.681 | E20: 57.767 | F20: -29.859 | G20: -31.832 | H20: 8.265
A21: Other Accruals | B21: 25.103 | C21: 0.319 | D21: 38.505 | E21: 15.245 | F21: 5.527 | G21: 52.895 | H21: 92.492
A22: Other Assets/Liabilities | B22: 276.987 | C22: 134.189 | D22: -349.467 | E22: -129.827 | F22: -165.252 | G22: 91.332 | H22: 65.9
A23: Net Operating Cash Flow | B23: -39.012 | C23: -165.215 | D23: -296.608 | E23: 333.851 | F23: 223.737 | G23: 712.183 | H23: 994.71
A24: Investing Activities
A25: Capital Expenditures | B25: -15.404 | C25: -13.096 | D25: -12.236 | E25: -12.627 | F25: -40.027 | G25: -15.114 | H25: -14.388
A26: Capital Expenditures (Fixed Assets) | B26: -15.404 | C26: -13.096 | D26: -12.236 | E26: -12.627 | F26: -40.027 | G26: -15.114 | H26: -14.388
A27: Net Assets from Acquisitions | B27: 0 | C27: 0 | D27: 0 | E27: 0 | F27: 66.708 | G27: 0 | H27: 0
A28: Sale of Fixed Assets & Businesses | B28: 8.62 | C28: 0 | D28: 0.25 | E28: 0 | F28: 0 | G28: 0 | H28: 0
A29: Purchase/Sale of Investments | B29: 0 | C29: -8.868 | D29: -2.934 | E29: -382.265 | F29: -72.181 | G29: -2696.066 | H29: -1531.687
A30: Purchase of Investments | B30: 0 | C30: 25.868 | D30: 2.934 | E30: 382.265 | F30: 124.5 | G30: 5636.406 | H30: 4263.435
A31: Sale/Maturity of Investments | B31: 0 | C31: 17 | D31: 0 | E31: 0 | F31: 52.319 | G31: 2940.34 | H31: 2731.748
A32: Other Funds | B32: 0 | C32: 0 | D32: 0 | E32: -3.02 | F32: 0.073 | G32: 0 | H32: -4
A33: Other Uses | B33: 0 | C33: 0 | D33: 0 | E33: -3.02 | F33: 0 | G33: 0 | H33: -4
A34: Other Sources | B34: 0 | C34: 0 | D34: 0 | E34: 0 | F34: 0.073 | G34: 0 | H34: 0
A35: Net Investing Cash Flow | B35: -6.784 | C35: -21.964 | D35: -14.92 | E35: -397.912 | F35: -45.427 | G35: -2711.18 | H35: -1550.075
A36: Financing Activities
A37: Change in Capital Stock | B37: 101.445 | C37: -68.678 | D37: 1237.581 | E37: 0 | F37: 86.089 | G37: 218.238 | H37: 276.018
A38: Repurchase of Common & Preferred Stk. | B38: -7.706 | C38: -193.075 | D38: -3.777 | E38: 0 | F38: 0 | G38: 0 | H38: -45.598
A39: Sale of Common & Preferred Stock | B39: 109.151 | C39: 124.397 | D39: 1241.358 | E39: 0 | F39: 86.089 | G39: 218.238 | H39: 321.616
A40: Proceeds from Sale of Stock | B40: 96.48 | C40: 107.5 | D40: 942.529 | E40: 0 | F40: 0 | G40: 0 | H40: 0
A41: Proceeds from Stock Options | B41: 12.671 | C41: 16.897 | D41: 298.829 | E41: 0 | F41: 86.089 | G41: 218.238 | H41: 321.616
A42: Issuance/Reduction of Debt, Net | B42: -56.491 | C42: 394.413 | D42: -200.631 | E42: 307.455 | F42: 0 | G42: 0 | H42: 0
...

Sheet CFS - Quarterly
A1: Palantir Technologies Inc. Class A (PLTR)
A2: $68.91
A5: Palantir Technologies Inc. Class A
A6: PLTR 69608A108 BN78DQ4 NASDAQ Common stock
A7: Source: FactSet Fundamentals
B8: JUN '22 | C8: SEP '22 | D8: DEC '22 | E8: MAR '23 | F8: JUN '23 | G8: SEP '23 | H8: DEC '23 | I8: MAR '24 | J8: JUN '24 | K8: SEP '24
A9: Operating Activities
A10: Net Income / Starting Line | B10: -179.329 | C10: -123.875 | D10: 33.489 | E10: 19.151 | F10: 27.872 | G10: 73.439 | H10: 96.913 | I10: 106.071 | J10: 135.57 | K10: 149.341
A11: Depreciation, Depletion & Amortization | B11: 4.895 | C11: 5.942 | D11: 7.373 | E11: 8.32 | F11: 8.399 | G11: 8.663 | H11: 7.972 | I11: 8.438 | J11: 8.056 | K11: 8.087
A12: Depreciation and Depletion | B12: 4.895 | C12: 5.942 | D12: 7.373 | E12: 8.32 | F12: 8.399 | G12: 8.663 | H12: 7.972 | I12: 8.438 | J12: 8.056 | K12: 1.706
A13: Deferred Taxes & Investment Tax Credit | B13: -0.011 | C13: -0.017 | D13: -0.143 | E13: 0 | F13: 0 | G13: 0 | H13: -4.806 | I13: 0 | J13: 0 | K13: 0
A14: Deferred Taxes | B14: -0.011 | C14: -0.017 | D14: -0.143 | E14: 0 | F14: 0 | G14: 0 | H14: -4.806 | I14: 0 | J14: 0 | K14: 0
A15: Other Funds | B15: 293.444 | C15: 215.593 | D15: 110.992 | E15: 111.88 | F15: 112.854 | G15: 117.001 | H15: 118.289 | I15: 131.69 | J15: 140.634 | K15: 179.904
A16: Funds from Operations | B16: 118.999 | C16: 97.643 | D16: 151.711 | E16: 150.187 | F16: 138.289 | G16: 199.103 | H16: 218.368 | I16: 246.199 | J16: 284.26 | K16: 337.332
A17: Changes in Working Capital | B17: -56.568 | C17: -50.577 | D17: -72.948 | E17: 37.189 | F17: -48.097 | G17: -65.66 | H17: 82.804 | I17: -116.62 | J17: -140.073 | K17: 82.44
A18: Receivables | B18: -9.872 | C18: -78.852 | D18: 77.072 | E18: -0.628 | F18: -113.035 | G18: -46.089 | H18: 53.593 | I18: -121.884 | J18: -176.427 | K18: -13.388
A19: Accounts Payable | B19: 27.419 | C19: 4.82 | D19: -14.694 | E19: -39.921 | F19: 0.864 | G19: 6.67 | H19: 0.555 | I19: 23.809 | J19: 29.563 | K19: -45.662
A20: Other Accruals | B20: 34.184 | C20: -29.678 | D20: 6.355 | E20: 4.271 | F20: 9.509 | G20: -11.228 | H20: 50.343 | I20: -19.105 | J20: -11.443 | K20: 72.697
A21: Other Assets/Liabilities | B21: -108.299 | C21: 53.133 | D21: -141.681 | E21: 73.467 | F21: 54.565 | G21: -15.013 | H21: -21.687 | I21: 0.56 | J21: 18.234 | K21: 68.793
A22: Net Operating Cash Flow | B22: 62.431 | C22: 47.066 | D22: 78.763 | E22: 187.376 | F22: 90.192 | G22: 133.443 | H22: 301.172 | I22: 129.579 | J22: 144.187 | K22: 419.772
A23: Investing Activities
A24: Capital Expenditures | B24: -5.458 | C24: -14.436 | D24: -4.918 | E24: -4.755 | F24: -3.934 | G24: -1.565 | H24: -4.86 | I24: -2.664 | J24: -2.879 | K24: -3.985
A25: Capital Expenditures (Fixed Assets) | B25: -5.458 | C25: -14.436 | D25: -4.918 | E25: -4.755 | F25: -3.934 | G25: -1.565 | H25: -4.86 | I25: -2.664 | J25: -2.879 | K25: -3.985
A26: Net Assets from Acquisitions | B26: 0 | C26: 0 | D26: 66.708 | E26: 0 | F26: 0 | G26: 0 | H26: 0 | I26: 0 | J26: 0 | K26: 0
A27: Purchase/Sale of Investments | B27: 10.762 | C27: -12.908 | D27: 11.218 | E27: -1549.836 | F27: -387.165 | G27: -194.699 | H27: -564.366 | I27: -508.581 | J27: -141.999 | K27: -316.741
A28: Purchase of Investments | B28: 0 | C28: 35 | D28: 0 | E28: 2310.367 | F28: 626.572 | G28: 1854.731 | H28: 844.736 | I28: 1260.327 | J28: 523.788 | K28: 1634.584
A29: Sale/Maturity of Investments | B29: 10.762 | C29: 22.092 | D29: 11.218 | E29: 760.531 | F29: 239.407 | G29: 1660.032 | H29: 280.37 | I29: 751.746 | J29: 381.789 | K29: 1317.843
A30: Other Funds | B30: 0 | C30: 0 | D30: 0.073 | E30: 0 | F30: 0 | G30: 0 | H30: 0 | I30: 0 | J30: -4 | K30: 0
A31: Other Uses | B31: 0 | C31: 0 | D31: 0 | E31: 0 | F31: 0 | G31: 0 | H31: 0 | I31: 0 | J31: -4 | K31: 0
A32: Other Sources | B32: 0 | C32: 0 | D32: 0.073 | E32: 0 | F32: 0 | G32: 0 | H32: 0 | I32: 0 | J32: 0 | K32: 0
A33: Net Investing Cash Flow | B33: 5.304 | C33: -27.344 | D33: 73.081 | E33: -1554.591 | F33: -391.099 | G33: -196.264 | H33: -569.226 | I33: -511.245 | J33: -148.878 | K33: -320.726
A34: Financing Activities
A35: Change in Capital Stock | B35: 20.316 | C35: 24.567 | D35: 13.981 | E35: 25.924 | F35: 90.349 | G35: 50.556 | H35: 51.409 | I35: 74.84 | J35: -1.669 | K35: 151.438
A36: Repurchase of Common & Preferred Stk. | B36: 0 | C36: 0 | D36: 0 | E36: 0 | F36: 0 | G36: 0 | H36: 0 | I36: -9 | J36: -17.699 | K36: -18.899
A37: Sale of Common & Preferred Stock | B37: 20.316 | C37: 24.567 | D37: 13.981 | E37: 25.924 | F37: 90.349 | G37: 50.556 | H37: 51.409 | I37: 83.84 | J37: 16.03 | K37: 170.337
A38: Proceeds from Stock Options | B38: 20.316 | C38: 24.567 | D38: 13.981 | E38: 25.924 | F38: 90.349 | G38: 50.556 | H38: 51.409 | I38: 83.84 | J38: 16.03 | K38: 170.337
A39: Other Funds | B39: 0.291 | C39: -0.576 | D39: 0.176 | E39: 0.059 | F39: 0.335 | G39: 0.384 | H39: -0.177 | I39: 0.408 | J39: -0.306 | K39: -0.011
A40: Other Uses | B40: 0 | C40: -0.269 | D40: 0.176 | E40: 0 | F40: 0 | G40: 0 | H40: 0 | I40: 0 | J40: 0 | K40: 0
A41: Other Sources | B41: 0.291 | C41: -0.307 | D41: 0 | E41: 0.059 | F41: 0.335 | G41: 0.384 | H41: -0.177 | I41: 0.408 | J41: -0.306 | K41: -0.011
A42: Net Financing Cash Flow | B42: 20.607 | C42: 23.991 | D42: 14.157 | E42: 25.983 | F42: 90.684 | G42: 50.94 | H42: 51.232 | I42: 75.248 | J42: -1.975 | K42: 151.427
...
